<?xml version="1.0" encoding="utf-8"?>
<!-- This URDF was automatically created by SolidWorks to URDF Exporter! Originally created by Stephen Brawner (brawner@gmail.com) 
     Commit Version: 1.6.0-4-g7f85cfe  Build Version: 1.6.7995.38578
     For more information, please see http://wiki.ros.org/sw_urdf_exporter -->
<robot
  name="mz04">
  <link
    name="base_link">
    <inertial>
      <origin
        xyz="-0.044759 -3.1086E-05 0.085751"
        rpy="0 0 0" />
      <mass
        value="3.513" />
      <inertia
        ixx="0.01237"
        ixy="4.9095E-06"
        ixz="-0.00013226"
        iyy="0.015585"
        iyz="-1.7141E-05"
        izz="0.013462" />
    </inertial>
    <visual>
      <origin
        xyz="0 0 0"
        rpy="0 0 0" />
      <geometry>
        <mesh
          filename="package://mz04/meshes/base_link.STL" />
      </geometry>
      <material
        name="">
        <color
          rgba="1 1 1 1" />
      </material>
    </visual>
    <collision>
      <origin
        xyz="0 0 0"
        rpy="0 0 0" />
      <geometry>
        <mesh
          filename="package://mz04/meshes/base_link.STL" />
      </geometry>
    </collision>
  </link>
  <link
    name="Link1">
    <inertial>
      <origin
        xyz="-0.019703 0.00093833 0.086517"
        rpy="0 0 0" />
      <mass
        value="3.292" />
      <inertia
        ixx="0.022229"
        ixy="-6.0946E-05"
        ixz="-0.0017533"
        iyy="0.015417"
        iyz="-0.00025811"
        izz="0.015073" />
    </inertial>
    <visual>
      <origin
        xyz="0 0 0"
        rpy="0 0 0" />
      <geometry>
        <mesh
          filename="package://mz04/meshes/Link1.STL" />
      </geometry>
      <material
        name="">
        <color
          rgba="1 1 1 1" />
      </material>
    </visual>
    <collision>
      <origin
        xyz="0 0 0"
        rpy="0 0 0" />
      <geometry>
        <mesh
          filename="package://mz04/meshes/Link1.STL" />
      </geometry>
    </collision>
  </link>
  <joint
    name="J1"
    type="revolute">
    <origin
      xyz="0 0 0.17"
      rpy="0 0 0" />
    <parent
      link="base_link" />
    <child
      link="Link1" />
    <axis
      xyz="0 0 -1" />
    <limit
      lower="-2.97"
      upper="2.97"
      effort="100"
      velocity="1" />
  </joint>
  <link
    name="Link2">
    <inertial>
      <origin
        xyz="-0.022943 -0.12931 -0.0008574"
        rpy="0 0 0" />
      <mass
        value="3.4334" />
      <inertia
        ixx="0.037485"
        ixy="-0.00057779"
        ixz="6.6852E-05"
        iyy="0.014046"
        iyz="0.00037774"
        izz="0.030147" />
    </inertial>
    <visual>
      <origin
        xyz="0 0 0"
        rpy="0 0 0" />
      <geometry>
        <mesh
          filename="package://mz04/meshes/Link2.STL" />
      </geometry>
      <material
        name="">
        <color
          rgba="1 1 1 1" />
      </material>
    </visual>
    <collision>
      <origin
        xyz="0 0 0"
        rpy="0 0 0" />
      <geometry>
        <mesh
          filename="package://mz04/meshes/Link2.STL" />
      </geometry>
    </collision>
  </link>
  <joint
    name="J2"
    type="revolute">
    <origin
      xyz="0 0 0.17"
      rpy="-1.5708 0 0" />
    <parent
      link="Link1" />
    <child
      link="Link2" />
    <axis
      xyz="0 0 1" />
    <limit
      lower="-2.53"
      upper="1.57"
      effort="100"
      velocity="1" />
  </joint>
  <link
    name="Link3">
    <inertial>
      <origin
        xyz="-0.0002808 -0.0055748 -0.0002648"
        rpy="0 0 0" />
      <mass
        value="1.7578" />
      <inertia
        ixx="0.0032265"
        ixy="0.00019114"
        ixz="5.2542E-06"
        iyy="0.0032168"
        iyz="-1.2185E-06"
        izz="0.0039061" />
    </inertial>
    <visual>
      <origin
        xyz="0 0 0"
        rpy="0 0 0" />
      <geometry>
        <mesh
          filename="package://mz04/meshes/Link3.STL" />
      </geometry>
      <material
        name="">
        <color
          rgba="1 1 1 1" />
      </material>
    </visual>
    <collision>
      <origin
        xyz="0 0 0"
        rpy="0 0 0" />
      <geometry>
        <mesh
          filename="package://mz04/meshes/Link3.STL" />
      </geometry>
    </collision>
  </link>
  <joint
    name="J3"
    type="revolute">
    <origin
      xyz="0 -0.26 0"
      rpy="0 0 0" />
    <parent
      link="Link2" />
    <child
      link="Link3" />
    <axis
      xyz="0 0 -1" />
    <limit
      lower="-2.18"
      upper="4.88"
      effort="100"
      velocity="1" />
  </joint>
  <link
    name="Link4">
    <inertial>
      <origin
        xyz="-0.0033404 0.00014789 -0.10747"
        rpy="0 0 0" />
      <mass
        value="1.3232" />
      <inertia
        ixx="0.0059296"
        ixy="-3.8706E-07"
        ixz="-2.9647E-05"
        iyy="0.0054197"
        iyz="-6.0665E-06"
        izz="0.0020314" />
    </inertial>
    <visual>
      <origin
        xyz="0 0 0"
        rpy="0 0 0" />
      <geometry>
        <mesh
          filename="package://mz04/meshes/Link4.STL" />
      </geometry>
      <material
        name="">
        <color
          rgba="1 1 1 1" />
      </material>
    </visual>
    <collision>
      <origin
        xyz="0 0 0"
        rpy="0 0 0" />
      <geometry>
        <mesh
          filename="package://mz04/meshes/Link4.STL" />
      </geometry>
    </collision>
  </link>
  <joint
    name="J4"
    type="revolute">
    <origin
      xyz="0.28 -0.025 0"
      rpy="1.5708 0 1.5708" />
    <parent
      link="Link3" />
    <child
      link="Link4" />
    <axis
      xyz="0 0 -1" />
    <limit
      lower="-3.32"
      upper="3.32"
      effort="100"
      velocity="1" />
  </joint>
  <link
    name="Link5">
    <inertial>
      <origin
        xyz="-8.6841E-06 5.4256E-06 -0.045863"
        rpy="0 0 0" />
      <mass
        value="1.1274E-05" />
      <inertia
        ixx="3.8792E-10"
        ixy="-5.826E-12"
        ixz="7.4597E-16"
        iyy="3.9514E-10"
        iyz="-4.3813E-15"
        izz="7.8265E-10" />
    </inertial>
    <visual>
      <origin
        xyz="0 0 0"
        rpy="0 0 0" />
      <geometry>
        <mesh
          filename="package://mz04/meshes/Link5.STL" />
      </geometry>
      <material
        name="">
        <color
          rgba="1 1 1 1" />
      </material>
    </visual>
    <collision>
      <origin
        xyz="0 0 0"
        rpy="0 0 0" />
      <geometry>
        <mesh
          filename="package://mz04/meshes/Link5.STL" />
      </geometry>
    </collision>
  </link>
  <joint
    name="J5"
    type="revolute">
    <origin
      xyz="0 0 0"
      rpy="1.5708 -1.5708 0" />
    <parent
      link="Link4" />
    <child
      link="Link5" />
    <axis
      xyz="0 0 1" />
    <limit
      lower="-2.09"
      upper="2.09"
      effort="100"
      velocity="1" />
  </joint>
  <link
    name="Link6">
    <inertial>
      <origin
        xyz="-0.00020474 -5.6356E-05 0.068551"
        rpy="0 0 0" />
      <mass
        value="0.034007" />
      <inertia
        ixx="8.7249E-06"
        ixy="5.054E-08"
        ixz="7.4434E-09"
        iyy="8.5826E-06"
        iyz="2.1149E-09"
        izz="1.6179E-05" />
    </inertial>
    <visual>
      <origin
        xyz="0 0 0"
        rpy="0 0 0" />
      <geometry>
        <mesh
          filename="package://mz04/meshes/Link6.STL" />
      </geometry>
      <material
        name="">
        <color
          rgba="1 1 1 1" />
      </material>
    </visual>
    <collision>
      <origin
        xyz="0 0 0"
        rpy="0 0 0" />
      <geometry>
        <mesh
          filename="package://mz04/meshes/Link6.STL" />
      </geometry>
    </collision>
  </link>
  <joint
    name="J6"
    type="revolute">
    <origin
      xyz="0 0 0"
      rpy="1.5708 0 1.5708" />
    <parent
      link="Link5" />
    <child
      link="Link6" />
    <axis
      xyz="0 0 -1" />
    <limit
      lower="-6.28"
      upper="6.28"
      effort="100"
      velocity="1" />
  </joint>
  <link
    name="Tool">
    <inertial>
      <origin
        xyz="-0.00020474 -5.6356E-05 -0.0034494"
        rpy="0 0 0" />
      <mass
        value="0.034007" />
      <inertia
        ixx="8.7249E-06"
        ixy="5.054E-08"
        ixz="7.4434E-09"
        iyy="8.5826E-06"
        iyz="2.1149E-09"
        izz="1.6179E-05" />
    </inertial>
    <visual>
      <origin
        xyz="0 0 0"
        rpy="0 0 0" />
      <geometry>
        <mesh
          filename="package://mz04/meshes/Tool.STL" />
      </geometry>
      <material
        name="">
        <color
          rgba="1 1 1 1" />
      </material>
    </visual>
    <collision>
      <origin
        xyz="0 0 0"
        rpy="0 0 0" />
      <geometry>
        <mesh
          filename="package://mz04/meshes/Tool.STL" />
      </geometry>
    </collision>
  </link>
  <joint
    name="J7"
    type="fixed">
    <origin
      xyz="0 0 0.072"
      rpy="0 0 0" />
    <parent
      link="Link6" />
    <child
      link="Tool" />
    <axis
      xyz="0 0 0" />
  </joint>
</robot>